Workbook

Sheet Income_Statement
A1: Title | B1: 12/31/2025 | D1: 12/31/2024 | E1: 12/31/2023 | F1: 12/31/2022 | I1: Gross Profit 2025 | L1: Operating Income
A2: Total Revenue | B2: 47941000 | D2: 47061000 | E2: 45754000 | F2: 43004000 | I2: Revenue | J2: 47941000 | L2: Gross Profit | M2: 29544000
A3: Operating Revenue | B3: 47941000 | D3: 47061000 | E3: 45754000 | F3: 43004000 | I3: Cost of Revenue | J3: 18397000 | L3: Total Operating Expense | M3: 14633000
A4: Cost of Revenue | B4: 18397000 | D4: 18324000 | E4: 18520000 | F4: 18000000 | I4: Gross Profit | J4: 29544000 | M4: =M2-M3 -> 14911000
A5: Gross Profit | B5: 29544000 | D5: 28737000 | E5: 27234000 | F5: 25004000 | G5: =F3-F4 -> 25004000
A6: Operating Expense | B6: 14633000 | C6: =B7+B16+B15 -> 14633000 | D6: 14715000 | E6: 14136000 | F6: 12962000 | G6: =F7+F16 -> 12962000 | I6: Operating Expense 2025
A7: Selling General and Administrative | B7: 14521000 | D7: 14582000 | E7: 13972000 | F7: 12880000 | I7: Salaries and Wages | J7: 279000
A8: General & Administrative Expense | B8: 9121000 | D8: 9482000 | E8: 254000 | F8: 356000 | I8: Other G and A | J8: 8842000
A9: Salaries and Wages | B9: 279000 | D9: 286000 | E9: 254000 | F9: 356000 | I9: Selling & Marketing Expense | J9: 5400000
A10: Other G and A | B10: 8842000 | D10: 9196000 | E10: -- | F10: -- | J10: =SUM(J7:J9) -> 14521000
A11: Selling & Marketing Expense | B11: 5400000 | D11: 5100000 | E11: 7609000 | F11: 7086000 | I11: Amortization of Intangibles | J11: 15000
A12: Depreciation Amortization Depletion | B12: 15000 | D12: -- | E12: 15000 | F12: -- | I12: Other Operating Expenses | J12: 97000
A13: Depreciation & amortization | B13: 15000 | D13: -- | E13: 15000 | F13: -- | J13: =SUM(J11:J12) -> 112000
A14: Amortization | B14: 15000 | D14: -- | E14: 15000 | F14: -- | I14: Total | J14: =SUM(J7:J13) -> 29266000
A15: Amortization of Intangibles | B15: 15000 | D15: -- | E15: 15000 | F15: --
A16: Other Operating Expenses | B16: 97000 | D16: 133000 | E16: 164000 | F16: 82000
A17: Operating Income | B17: 14911000 | D17: 14022000 | E17: 13098000 | F17: 12042000 | G17: =F5-F6 -> 12042000
A18: Net Non Operating Interest Income Expense | B18: -868000 | C18: =B19-B20 -> -868000 | D18: -668000 | E18: -620000 | F18: -433000 | G18: =F19-F20 -> -433000
A19: Interest Income Non Operating | B19: 786000 | D19: 988000 | E19: 907000 | F19: 449000
A20: Interest Expense Non Operating | B20: 1654000 | D20: 1656000 | E20: 1527000 | F20: 882000
A21: Other Income Expense | B21: 1955000 | D21: -268000 | E21: 474000 | F21: 77000
A22: Gain on Sale of Security | B22: 520000 | D22: 315000 | E22: 185000 | F22: -496000
A23: Earnings from Equity Interest | B23: 2031000 | D23: 1770000 | E23: 1691000 | F23: 1472000
A24: Special Income Charges | B24: -501000 | D24: -2301000 | E24: -1787000 | F24: -1133000
A25: Restructuring & Mergers Acquisition | B25: 16000 | D25: 2246000 | E25: 1744000 | F25: 1076000
A26: Impairment of Capital Assets | B26: 1045000 | D26: 886000 | E26: -- | F26: 57000
A27: Write Off | B27: 65000 | D27: 34000 | E27: 39000 | F27: 96000
A28: Other Special Charges | B28: 10000 | D28: -23000 | E28: -42000 | F28: -219000
A29: Gain on Sale of Business | B29: 635000 | D29: 842000 | E29: -35000 | F29: --
A30: Gain on Sale of PPE | D30: -- | E30: -35000 | F30: --
A31: Other Non Operating Income Expenses | B31: -95000 | D31: -52000 | E31: 570000 | F31: -262000
A32: Pretax Income/EBIT | B32: 15998000 | D32: 13086000 | E32: 12952000 | F32: 11686000
A33: Tax Provision | B33: 2861000 | D33: 2437000 | E33: 2249000 | F33: 2115000
A34: Net Income Common Stockholders | B34: 13107000 | C34: =B32-B33+C38 -> 13137000 | D34: 10631000 | E34: 10714000 | F34: 9542000 | G34: =F32-F33+F38 -> 9542000
A35: Net Income | B35: 13107000 | D35: 10631000 | E35: 10714000 | F35: 9542000
A36: Net Income Including Non-Controlling Interests | B36: 13137000 | D36: 10649000 | E36: 10703000 | F36: 9571000
A37: Net Income Continuous Operations | B37: 13137000 | D37: 10649000 | E37: 10703000 | F37: 9571000
A38: Minority Interests | B38: -30000 | D38: -18000 | E38: 11000 | F38: -29000
A39: Diluted NI Available to Com Stockholders | B39: 13107000 | C39: =B32-B33+B38 -> 13107000 | D39: 10631000 | E39: 10714000 | F39: 9542000 | G39: =F32+F38-F33 -> 9542000
A40: Basic EPS | B40: 3.05 | D40: 2.47 | E40: 2.48 | F40: 2.2
...

Sheet Balance_sheet
A1: Title | B1: 12/31/2025 | D1: 12/31/2024 | E1: 12/31/2023 | F1: 12/31/2022 | I1: Current Assets 2025 | L1: Non-current assets 2025
A2: Total Assets | B2: 104816000 | D2: 100549000 | E2: 97703000 | F2: 92763000 | I2: Cash And Cash Equivalents | J2: 10270000 | L2: Land And Improvements | M2: 265000
A3: Current Assets | B3: 31044000 | C3: =C4+C8+C12+B17+B18 -> 31044000 | D3: 25997000 | E3: 26732000 | F3: 22591000 | I3: Other Short Term Investments | J3: 5536000 | L3: Buildings And Improvements | M3: 4967000
A4: Cash Cash Equivalents & Short Term Investments | B4: 15806000 | C4: =B5+B6 -> 15806000 | D4: 14571000 | E4: 13663000 | F4: 11631000 | G4: =SUM(F5:F6) -> 11631000 | I4: Gross Accounts Receivable | J4: 3533000 | L4: Machinery Furniture Equipment | M4: 13500000
A5: Cash And Cash Equivalents | B5: 10270000 | D5: 10828000 | E5: 9366000 | F5: 9519000 | I5: Allowance For Doubtful Accounts Receivable | J5: -495000 | L5: Accumulated Depreciation | M5: -9119000
A6: Other Short Term Investments | B6: 5536000 | D6: 3743000 | E6: 4297000 | F6: 2112000 | I6: Inventory | J6: 4425000 | L6: Goodwill And Other Intangible Assets | M6: 28022000
A7: Receivables | B7: 3038000 | D7: 3569000 | E7: 3410000 | F7: 3487000 | I7: Assets Held for Sale Current | J7: 5342000 | L7: Investments And Advances | M7: 20235000
A8: Accounts receivable | B8: 3038000 | C8: =B9+B10 -> 3038000 | D8: 3569000 | E8: 3410000 | F8: 3487000 | G8: =SUM(F9:F10) -> 3487000 | I8: Other Current Assets | J8: 2433000 | L8: Non Current Deferred Taxes Assets | M8: 1206000
A9: Gross Accounts Receivable | B9: 3533000 | D9: 4075000 | E9: 3912000 | F9: 4003000 | I9: Total | J9: =SUM(J2:J8) -> 31044000 | L9: Other Non Current Assets | M9: 14696000
A10: Allowance For Doubtful Accounts Receivable | B10: -495000 | D10: -506000 | E10: -502000 | F10: -516000 | L10: Total | M10: =SUM(M2:M9) -> 73772000
A12: Inventory | B12: 4425000 | C12: =B13+B14+B15 -> 4425000 | D12: 4728000 | E12: 4424000 | F12: 4233000 | G12: =SUM(F13:F15) -> 4233000
A13: Raw Materials | B13: 2708000 | D13: 2794000 | E13: 2618000 | F13: 2627000 | I13: Current Liabilities | L13: Total Non Current Liabilities
A14: Finished Goods | B14: 1375000 | D14: 1524000 | E14: 1449000 | F14: 1247000 | I14: Accounts Payable | J14: 5649000 | L14: Long Term Debt | M14: 42119000
A15: Other Inventories | B15: 342000 | D15: 410000 | E15: 357000 | F15: 359000 | I15: Total Tax Payable | J15: 525000 | L15: Non Current Deferred Liabilities | M15: 2406000
A16: Prepaid Assets | B16: -- | D16: -- | E16: -- | F16: 3240000 | I16: Current Accrued Expenses | J16: 7658000 | L16: Other Non Current Liabilities | M16: 4735000
A17: Assets Held for Sale Current | B17: 5342000 | D17: 131000 | E17: -- | F17: -- | I17: Pension & Other Post Retirement Benefit Plans Current | J17: 1506000 | L17: Total | M17: =SUM(M14:M16) -> 49260000
A18: Other Current Assets | B18: 2433000 | D18: 2998000 | E18: 5235000 | F18: 3240000 | I18: Current Debt | J18: 3373000
A19: Total non-current assets | B19: 73772000 | D19: 74552000 | E19: 70971000 | F19: 70172000 | I19: Other Current Liabilities | J19: 2570000
A20: Net PPE | B20: 9613000 | D20: 10303000 | E20: 9236000 | F20: 9841000 | I20: Total | J20: =SUM(J14:J19) -> 21281000
A21: Gross PPE | B21: 18732000 | D21: 19873000 | E21: 18469000 | F21: 19075000
A22: Properties | B22: 0 | D22: 0 | E22: 0 | F22: 0
A23: Land And Improvements | B23: 265000 | D23: 226000 | E23: 229000 | F23: 611000
A24: Buildings And Improvements | B24: 4967000 | D24: 5143000 | E24: 4647000 | F24: 4434000
A25: Machinery Furniture Equipment | B25: 13500000 | D25: 14504000 | E25: 13593000 | F25: 14030000
A26: Accumulated Depreciation | B26: -9119000 | D26: -9570000 | E26: -9233000 | F26: -9234000
A27: Goodwill And Other Intangible Assets | B27: 28022000 | C27: =B28+B29 -> 28022000 | D27: 31440000 | E27: 32707000 | F27: 33631000 | G27: =F28+F29 -> 33631000
A28: Goodwill | B28: 15491000 | D28: 18139000 | E28: 18358000 | F28: 18782000
A29: Other Intangible Assets | B29: 12531000 | D29: 13301000 | E29: 14349000 | F29: 14849000
A30: Investments And Advances | B30: 20235000 | D30: 18087000 | E30: 19671000 | F30: 18765000
A31: Long Term Equity Investment | B31: 20235000 | D31: 18087000 | E31: 19671000 | F31: 18264000
A32: Other Investments | B32: -- | D32: -- | E32: 118000 | F32: 501000
A33: Non Current Deferred Assets | B33: 1206000 | D33: 1319000 | E33: 1561000 | F33: 1746000
A34: Non Current Deferred Taxes Assets | B34: 1206000 | D34: 1319000 | E34: 1561000 | F34: 1746000
A35: Other Non Current Assets | B35: 14696000 | D35: 13403000 | E35: 7796000 | F35: 6189000
A36: Total Liabilities Net Minority Interest | B36: 70541000 | D36: 74177000 | E36: 70223000 | F36: 66937000
A37: Current Liabilities | B37: 21281000 | D37: 25249000 | E37: 23571000 | F37: 19724000
A38: Payables And Accrued Expenses | B38: 13832000 | C38: =B39+B44 -> 13832000 | D38: 21708000 | E38: 15660000 | F38: 15865000 | G38: =F39+F44 -> 15865000
A39: Payables | B39: 6174000 | C39: =B40+B41 -> 6174000 | D39: 6855000 | E39: 7159000 | F39: 6510000 | G39: =SUM(F40:F41) -> 6510000
A40: Accounts Payable | B40: 5649000 | D40: 5468000 | E40: 5590000 | F40: 5307000
A41: Total Tax Payable | B41: 525000 | D41: 1387000 | E41: 1569000 | F41: 1203000
...

Sheet CashFlow_statement
A1: Title | B1: 12/31/2025 | D1: 12/31/2024 | E1: 12/31/2023 | F1: 12/31/2022
A2: Operating Cash Flow | B2: 7408000 | D2: 6805000 | E2: 11599000 | F2: 11018000
A3: Cash Flow from Continuing Operating Activities | B3: 7408000 | D3: 6805000 | E3: 11599000 | F3: 11018000
A4: Net Income from Continuing Operations | B4: 13137000 | D4: 10649000 | E4: 10703000 | F4: 9571000
A5: Operating Gains Losses | B5: -847000 | D5: -912000 | E5: -844000 | F5: -635000
A6: Net Foreign Currency Exchange Gain Loss | B6: 191000 | D6: -110000 | E6: 175000 | F6: 203000
A7: Earnings Losses from Equity Investments | B7: -1038000 | D7: -802000 | E7: -1019000 | F7: -838000
A8: Depreciation Amortization Depletion | B8: 1050000 | D8: 1075000 | E8: 1128000 | F8: 1260000
A9: Depreciation & amortization | B9: 1050000 | D9: 1075000 | E9: 1128000 | F9: 1260000
A10: Deferred Tax | B10: 517000 | D10: -11000 | E10: -2000 | F10: -122000
A11: Deferred Income Tax | B11: 517000 | D11: -11000 | E11: -2000 | F11: -122000
A12: Stock based compensation | B12: 279000 | D12: 286000 | E12: 254000 | F12: 356000
A13: Other non-cash items | B13: 480000 | D13: 1952000 | E13: 1206000 | F13: 1193000
... A52: Beginning Cash Position | B52: 11488000 | D52: 9692000 | E52: 9825000 | F52: 10025000
A53: Other Cash Adjustment Outside Change in Cash | B53: -- | D53: -- | E53: -- | F53: --
A54: Capital Expenditure | B54: -2112000 | D54: -2064000 | E54: -1852000 | F54: -1484000
A55: Issuance of Capital Stock | B55: 313000 | D55: 747000 | E55: 539000 | F55: 837000
A56: Issuance of Debt | B56: 4980000 | D56: 12061000 | E56: 6891000 | F56: 3972000
A57: Repayment of Debt | B57: -4967000 | D57: -9533000 | E57: -5034000 | F57: -4930000
A58: Repurchase of Capital Stock | B58: -746000 | D58: -1795000 | E58: -2289000 | F58: -1418000
A59: Free Cash Flow | B59: 5296000 | D59: 4741000 | E59: 9747000 | F59: 9534000

Sheet Ratio&Valuation Analysis
A12: Financial Ratios
B13: Liquidity Ratios | H13: Profitabilit Ratios
C15: 2025 | D15: 2024 | I15: 2025 | J15: 2024
B16: Current Assets | C16: =Balance_sheet!B3 -> 31044000 | D16: =Balance_sheet!D3 -> 25997000 | H16: Revenue | I16: =Income_Statement!B3 -> 47941000 | J16: =Income_Statement!D3 -> 47061000
B17: Current Liabilities | C17: =Balance_sheet!B37 -> 21281000 | D17: =Balance_sheet!D37 -> 25249000 | H17: Gross Profit | I17: =Income_Statement!B5 -> 29544000 | J17: =Income_Statement!D5 -> 28737000
B18: Current Ratio | C18: =C16/C17 -> 1.458766 | D18: =D16/D17 -> 1.0296249 | H18: Gross Profit Margin | I18: =I17/I16 -> 0.61625748 | J18: =J17/J16 -> 0.61063301
B21: Current Assets | C21: =C16-Balance_sheet!$B$12 -> 26619000 | D21: =D16-Balance_sheet!D12 -> 21269000 | H21: Revenue | I21: 47941000 | J21: 47061000
B22: Current Liabilities | C22: 21281000 | D22: 25249000 | H22: Operating Income | I22: =Income_Statement!B17 -> 14911000 | J22: =Income_Statement!D17 -> 14022000
B23: Quick Ratio (Acid Test) | C23: =C21/C22 -> 1.2508341 | D23: =D21/D22 -> 0.84236999 | H23: Operating Profit Margin | I23: =I22/I21 -> 0.31102814 | J23: =J22/J21 -> 0.29795372
B26: Cash and Cash equivalents | C26: =Balance_sheet!B5 -> 10270000 | D26: =Balance_sheet!D5 -> 10828000 | H26: Revenue | I26: 47941000 | J26: 47061000
B27: Marketable securities | C27: =Balance_sheet!B6 -> 5536000 | D27: =Balance_sheet!D6 -> 3743000 | H27: Net Income | I27: =Income_Statement!B35 -> 13107000 | J27: =Income_Statement!D35 -> 10631000
B28: Current Liabilities | C28: 21281000 | D28: 25249000 | H28: Net Profit Margin | I28: =I27/I26 -> 0.27339855 | J28: =J27/J26 -> 0.2258983
B29: Cash Ratio | C29: =SUM(C26:C27)/C28 -> 0.74272826 | D29: =SUM(D26:D27)/D28 -> 0.57709216
B31: Ratio | C31: Result | D31: Strength | E31: Interpretation | H31: Net Income | I31: 13107000 | J31: 10631000
B32: Current Ratio | C32: 1.46 | D32: Strong | E32: Company can comfortably cover short‑term obligations. | H32: Total Assets | I32: =Balance_sheet!B2 -> 104816000 | J32: =Balance_sheet!D2 -> 100549000
B33: Quick Ratio (Acid Test) | C33: 1.23 | D33: Strong | E33: Liquidity remains solid even without inventory. | H33: ROA(Return on Assets) | I33: =I31/I32 -> 0.1250477 | J33: =J31/J32 -> 0.10572954
B34: Cash Ratio | C34: 0.74 | D34: Healthy | E34: Company has strong cash reserves relative to liabilities.
H36: Net Income | I36: 13107000 | J36: 10631000
H37: Shareholder’s equity | I37: =Balance_sheet!B59 -> 32169000 | J37: =Balance_sheet!D59 -> 24856000
H38: ROE (Return on Equity) | I38: =I36/I37 -> 0.40744195 | J38: =J36/J37 -> 0.42770357
G40: Ratio | H40: Result | I40: Strength | J40: Interpretation
G41: Gross Profit Margin | H41: 0.62 | I41: Excellent | J41: Strong control over production costs.
G42: Operating Profit Margin | H42: 0.31 | I42: Excellent | J42: Efficient operations and overhead management.
G43: Net Profit Margin | H43: 0.27 | I43: Excellent | J43: High overall profitability.
G44: ROA(Return on Assets) | H44: 0.13 | I44: Strong | J44: Assets are generating solid returns.
G45: ROE (Return on Equity) | H45: 0.41 | I45: Excellent | J45: Shareholders are receiving exceptional returns.
B47: Additional Ratios
B49: Net Income | C49: 13107000
B50: Number of Common Shares Outstanding | C50: =Balance_sheet!B80 -> 4301608.8
B51: Earnings per share | C51: =C49/C50 -> 3.0469995
B54: Price per common share | C54: 77.34
B55: Earnings per share | C55: =C51 -> 3.0469995
B56: Price/Earnings Ratio | C56: =C54/C55 -> 25.382347
B59: Total Dividend Paid | C59: 8779000
B60: Net Income | C60: 13107000
B61: Dividend Payout Ratio | C61: =C59/C60 -> 0.66979477
B64: Total Debt | C64: =Balance_sheet!B77 -> 45492000
B65: Total Equity | C65: =Balance_sheet!B59 -> 32169000
B66: Debt-to-Equity Ratio | C66: =C64/C65 -> 1.4141565
B69: ROE (Return on Equity) | C69: 0.40744195
...

Sheet Additional_Ratios
B2: Additional Ratios
H4: Additional Ratios
H6: Net Income | I6: 13107000
H7: Number of Common Shares Outstanding | I7: 4301608.8
H8: Earnings per share | I8: 3.0469995
H11: Price per common share | I11: 77.34
H12: Earnings per share | I12: 3.0469995
H13: Price/Earnings Ratio | I13: 25.382347
B15: Ratio | C15: Result | D15: Strength | E15: Interpretation
B16: Earnings per share | C16: 3.0469995 | D16: Strong | E16: High profit per share. | H16: Total Dividend Paid | I16: 8779000
B17: Price/Earnings Ratio | C17: 25.38 | D17: High | E17: Market expects growth. | H17: Net Income | I17: 13107000
B18: Dividend Payout Ratio | C18: 0.67 | D18: Moderate - High | E18: Shareholder‑friendly; less reinvestment. | H18: Dividend Payout Ratio | I18: 0.66979477
B19: Debt-to-Equity Ratio | C19: 1.41 | D19: Leveraged | E19: Debt boosts returns but adds risk.
B20: Sustainable Growth Rate | C20: 0.13 | D20: Excellent | E20: Strong internal growth capacity.
H21: Total Debt | I21: 45492000
H22: Total Equity | I22: 32169000
H23: Debt-to-Equity Ratio | I23: 1.4141565
H26: ROE (Return on Equity) | I26: 0.40744195
H27: Dividend Payout Ratio | I27: 0.66979477
H28: Sustainable Growth Rate | I28: 0.13453946

Sheet Liquidity_Ratios
B2: Liquidity Ratios
H3: Liquidity Ratios
I5: 2025 | J5: 2024
H6: Current Assets | I6: 31044000 | J6: 25997000
H7: Current Liabilities | I7: 21281000 | J7: 25249000
H8: Current Ratio | I8: 1.458766 | J8: 1.0296249
H11: Current Assets | I11: 26619000 | J11: 21269000
H12: Current Liabilities | I12: 21281000 | J12: 25249000
H13: Quick Ratio (Acid Test) | I13: 1.2508341 | J13: 0.84236999
B14: Ratio | C14: Result | D14: Strength | E14: Interpretation
B15: Current Ratio | C15: 1.46 | D15: Strong | E15: Company can comfortably cover short‑term obligations.
B16: Quick Ratio (Acid Test) | C16: 1.23 | D16: Strong | E16: Liquidity remains solid even without inventory. | H16: Cash and Cash equivalents | I16: 10270000 | J16: 10828000
B17: Cash Ratio | C17: 0.74 | D17: Healthy | E17: Company has strong cash reserves relative to liabilities. | H17: Marketable securities | I17: 5536000 | J17: 3743000
H18: Current Liabilities | I18: 21281000 | J18: 25249000
H19: Cash Ratio | I19: 0.74272826 | J19: 0.57709216

Sheet Profitability_ratio
B2: Profitabilit Ratios
G3: Profitabilit Ratios
H5: 2025 | I5: 2024
G6: Revenue | H6: 47941000 | I6: 47061000
G7: Gross Profit | H7: 29544000 | I7: 28737000
G8: Gross Profit Margin | H8: 0.61625748 | I8: 0.61063301
G11: Revenue | H11: 47941000 | I11: 47061000
G12: Operating Income | H12: 14911000 | I12: 14022000
B13: Ratio | C13: Result | D13: Strength | E13: Interpretation | G13: Operating Profit Margin | H13: 0.31102814 | I13: 0.29795372
B14: Gross Profit Margin | C14: 0.62 | D14: Excellent | E14: Strong control over production costs.
B15: Operating Profit Margin | C15: 0.31 | D15: Excellent | E15: Efficient operations and overhead management.
B16: Net Profit Margin | C16: 0.27 | D16: Excellent | E16: High overall profitability. | G16: Revenue | H16: 47941000 | I16: 47061000
B17: ROA(Return on Assets) | C17: 0.13 | D17: Strong | E17: Assets are generating solid returns. | G17: Net Income | H17: 13107000 | I17: 10631000
B18: ROE (Return on Equity) | C18: 0.41 | D18: Excellent | E18: Shareholders are receiving exceptional returns. | G18: Net Profit Margin | H18: 0.27339855 | I18: 0.2258983
G21: Net Income | H21: 13107000 | I21: 10631000
G22: Total Assets | H22: 104816000 | I22: 100549000
G23: ROA(Return on Assets) | H23: 0.1250477 | I23: 0.10572954
G26: Net Income | H26: 13107000 | I26: 10631000
G27: Shareholder’s equity | H27: 32169000 | I27: 24856000
G28: ROE (Return on Equity) | H28: 0.40744195 | I28: 0.42770357

Sheet Charts_Ratios
A1: Profitability Margins | K1: Liquidity Ratios
A2: Ratios | B2: Value | K2: Ratios | L2: Value
A3: Gross Profit Margin | B3: 0.62 | K3: Current Ratio | L3: 1.458766
A4: Operating Profit Margin | B4: 0.31 | K4: Quick Ratio (Acid Test) | L4: 1.2508341
A5: Net Profit Margin | B5: 0.27 | K5: Cash Ratio | L5: 0.74272826
K19: Additional Ratios
A20: Return Ratios | K20: Ratios | L20: Value
A21: Ratios | B21: Value | K21: Earnings per share | L21: 3.0469995
A22: ROA(Return on Assets) | B22: 0.13 | K22: Price/Earnings Ratio | L22: 25.382347
A23: ROE (Return on Equity) | B23: 0.41 | K23: Dividend Payout Ratio | L23: 0.66979477
K34: Ratios | L34: Value
K35: Debt-to-Equity Ratio | L35: 1.4141565
K36: Sustainable Growth Rate | L36: 0.13453946
